2024-08-22 12:47:57,022 - ERROR - An error occurred: exceptions must derive from BaseException
Traceback (most recent call last):
  File "lib\main_engine.py", line 164, in _run_animation
    animator.parse_gcode()
  File "lib\animation.py", line 43, in parse_gcode
    with open(self.gcode_file, 'r') as file:
TypeError: expected str, bytes or os.PathLike object, not NoneType

During handling of the above exception, another exception occurred:

Traceback (most recent call last):
  File "main.py", line 29, in main
    main_client.cli()
  File "lib\main_engine.py", line 226, in cli
    self._run_animation()
  File "lib\main_engine.py", line 182, in _run_animation
    raise(f"An unexpected error occurred: {e}")
TypeError: exceptions must derive from BaseException
2024-08-22 12:50:52,515 - ERROR - An error occurred: exceptions must derive from BaseException
Traceback (most recent call last):
  File "C:\Users\prali\Desktop\Pralish\Emplyment Work\University Work\Software\SupremeSlicer\supremeslicer\lib\main_engine.py", line 164, in _run_animation
    animator.parse_gcode()
  File "C:\Users\prali\Desktop\Pralish\Emplyment Work\University Work\Software\SupremeSlicer\supremeslicer\lib\animation.py", line 43, in parse_gcode
    with open(self.gcode_file, 'r') as file:
TypeError: expected str, bytes or os.PathLike object, not NoneType

During handling of the above exception, another exception occurred:

Traceback (most recent call last):
  File ".\main.py", line 29, in main
    main_client.cli()
  File "C:\Users\prali\Desktop\Pralish\Emplyment Work\University Work\Software\SupremeSlicer\supremeslicer\lib\main_engine.py", line 226, in cli
    self._run_animation()
  File "C:\Users\prali\Desktop\Pralish\Emplyment Work\University Work\Software\SupremeSlicer\supremeslicer\lib\main_engine.py", line 182, in _run_animation
    raise(f"An unexpected error occurred: {e}")
TypeError: exceptions must derive from BaseException
2024-08-22 12:51:51,287 - ERROR - An error occurred: invalid literal for int() with base 10: '0.1'
Traceback (most recent call last):
  File ".\main.py", line 29, in main
    main_client.cli()
  File "C:\Users\prali\Desktop\Pralish\Emplyment Work\University Work\Software\SupremeSlicer\supremeslicer\lib\main_engine.py", line 222, in cli
    self._run_tools()
  File "C:\Users\prali\Desktop\Pralish\Emplyment Work\University Work\Software\SupremeSlicer\supremeslicer\lib\main_engine.py", line 115, in _run_tools
    self._vacuum_tool()
  File "C:\Users\prali\Desktop\Pralish\Emplyment Work\University Work\Software\SupremeSlicer\supremeslicer\lib\main_engine.py", line 89, in _vacuum_tool
    user_in = int(input())
ValueError: invalid literal for int() with base 10: '0.1'
